Workbook

Sheet Modelo
H5: Transaccion
D6: Estrategias | H6: codTRX
B7: Cliente | D7: cod_estrategia | H7: Tipo_TRX
B8: cod_cliente | D8: nombre_estrategia | H8: cod_protocolo
B9: nombre | D9: tipo_estrategia | H9: estado
B10: dni | D10: cod_gesto
B11: tipo_cliente | D11: min interes
B12: edad | D12: max interes
B13: sexo
H17: MOV-INTERACCIONES
H18: canal
H19: correlativo
H20: id_interaccion
H21: cod_cliente
H22: cod_estrategia
H23: cod_gesto
H24: cod_producto
H25: tipo_transaccion
H26: fecha
H27: hora
H28: nivel_de_interes
D30: Cuenta-Productos
D31: cod_lote_producto
D32: nombre_producto
D33: fecha_creacion_stock
D34: total_disponible
D35: total_vendidos
D36: total_veces_mostrado
D37: estado_producto
H43: canal
H44: correlativo
H45: cod_cliente
H46: cod_estrategia
H47: tipo_transaccion
H48: fecha
H49: hora

Sheet TABLA PROPUESTAS
J4: TABLAS MAESTRAS
J5: MAESTRA - PRODUCTOS
J6: Atributo | K6: Tipo | L6: Tamaño | M6: Clave | O6: Diseño Físico
J7: cod_lote_producto | K7: char | L7: 8 | M7: PK | O7: Nombre | P7: MAESTRA - PRODUCTOS
J8: nombre_producto | K8: varchar | L8: 20 | M8: SK | O8: Organización | P8: indexada
J9: fecha_creacion_stock | K9: date | L9: 8 | M9: -- | O9: Longitud de Registro | P9: (53,53)
J10: total_disponible | K10: int | L10: 4 | M10: -- | O10: IC | P10: 1024
J11: total_vendidos | K11: int | L11: 4 | M11: -- | O11: Capacidad | P11: N=1000000, AC=19*12*18
J12: cierres_venta
J13: total_veces_mostrado | K13: int | L13: 4 | M13: --
A14: TABLAS DE MOVIMIENTOS | J14: estado_producto | K14: char | L14: 1 | M14: --
A15: BITÁCORA INTERACCIONES
A16: Atributo | B16: Tipo | C16: Tamaño | D16: Clave
A17: canal | B17: char | C17: 1 | D17: PK
A18: correlativo | B18: int | C18: 4 | F18: Nombre | G18: BITÁCORA INTERACCIONES | J18: MAESTRA - CLIENTES
A19: cod_cliente | B19: char | C19: 8 | D19: SK | F19: Organización | G19: Indexado | J19: Atributo | K19: Tipo | L19: Tamaño | M19: Clave
A20: id_proceso_venta | B20: date | C20: 6 | F20: Longitud de Registro | G20: (67,67) | J20: cod_cliente | K20: char | L20: 8 | M20: PK
A21: tipo_cliente | B21: char | C21: 4 | D21: FK | F21: IC | G21: 512 | J21: nombre_cliente | K21: varchar | L21: 20 | M21: SK | O21: Nombre | P21: MAESTRA - CLIENTES
A22: cod_estrategia | B22: char | C22: 8 | D22: FK | F22: Capacidad | G22: N=1000000, AC= 19*24*7 | J22: fecha_ingreso | K22: date | L22: 8 | M22: -- | O22: Organización | P22: indexada
A23: cod_gesto | B23: char | C23: 8 | D23: FK | J23: cant_entradas | K23: int | L23: 7 | M23: -- | O23: Longitud de Registro | P23: (68,68)
A24: cod_producto | B24: char | C24: 8 | D24: FK | J24: total_cierres_ventas | K24: int | L24: 6 | M24: -- | O24: IC | P24: 512
A25: tipo_transaccion | B25: char | C25: 4 | D25: -- | J25: última_visita | K25: date | L25: 8 | M25: -- | O25: Capacidad | P25: N=1000000, AC= 19*24*7
A26: fecha | B26: date | C26: 8 | D26: -- | J26: estado_cliente | K26: char | L26: 1 | M26: --
A27: hora | B27: date | C27: 8 | D27: --
A28: nivel_de_interes | B28: float | C28: 2 | D28: --
J32: MAESTRA - ESTRATEGIAS
A33: BITÁCORA VENTAS | J33: Atributo | K33: Tipo | L33: Tamaño | M33: Clave
A34: Atributo | B34: Tipo | C34: Tamaño | D34: Clave | J34: cod_estrategia | K34: char | L34: 8 | M34: PK | O34: Nombre | P34: MAESTRA - ESTRATEGIAS
A35: canal | B35: =VLOOKUP(A35, 'Hoja 1'!$A$43:$D$57, 2, FALSE) -> #REF! | C35: 1 | D35: PK | F35: Nombre | G35: BITÁCORA VENTAS | J35: nombre_estrategia | K35: varchar | L35: 20 | M35: SK | O35: Organización | P35: indexada
A36: correlativo | B36: =VLOOKUP(A36, 'Hoja 1'!$A$43:$D$57, 2, FALSE) -> #REF! | C36: 4 | F36: Organización | G36: Indexado | J36: tipo_cliente | K36: char | L36: 6 | M36: -FK | O36: Longitud de Registro | P36: (37,37)
A37: cod_cliente | B37: =VLOOKUP(A37, 'Hoja 1'!$A$43:$D$57, 2, FALSE) -> #REF! | C37: 8 | D37: SK | F37: Longitud de Registro | G37: (41,41) | J37: total_veces_aplicada | K37: int | L37: 4 | M37: -- | O37: IC | P37: 1536
A38: cod_producto | B38: char | C38: 8 | D38: FK | E38: FK | F38: IC | G38: 1024 | J38: ventas_generadas | K38: int | L38: 4 | M38: -- | O38: Capacidad | P38: N=1000000, AC= 19*6*38
A39: cantidad | B39: int | C39: 3 | D39: --- | F39: Capacidad | G39: N=1000000, AC= 19*12*23 | J39: estado | K39: char | L39: 1 | M39: --
A40: cod_estrategia | B40: =VLOOKUP(A40, 'Hoja 1'!$A$43:$D$57, 2, FALSE) -> #REF! | C40: 8 | D40: FK
A41: tipo_transaccion | B41: =VLOOKUP(A41, 'Hoja 1'!$A$43:$D$57, 2, FALSE) -> #REF! | C41: 4 | D41: --
A42: fecha | B42: =VLOOKUP(A42, 'Hoja 1'!$A$43:$D$57, 2, FALSE) -> #REF! | C42: 8 | D42: -- | J42: E1
A43: hora | B43: =VLOOKUP(A43, 'Hoja 1'!$A$43:$D$57, 2, FALSE) -> #REF! | C43: 8 | D43: -- | J43: E2
J44: E3
J45: E4
A46: BITÁCORA DETALLE VENTA
...

Sheet Consulta crítica
E2: Consulta de Cierres de venta por Tipo de producto
K3: Maestra clientes | M3: cod_cliente | N3: nombre | O3: apellido
F4: Tipo de producto | G4: T00002 | K4: Maestra productos | M4: cod_producto | N4: nombre | O4: tipo_producto | P4: total_ventasxtipoProducto (se conseguira a treves de calculo)
K5: Estrategias | M5: cod_estrategia | N5: nombre_estrategia
K6: bitacora venta | M6: cantidad | N6: fecha | O6: hora
F7: Nombre tipo | G7: Casaca
C13: cod cliente | D13: nombre | E13: apellido | F13: cod_producto | G13: nombre_producto | H13: cantidad | I13: cod_estrategia | J13: nombre_estrategia | K13: fecha | L13: hora
C14: C0000001 | D14: Diego | E14: Moran | F14: P0000001 | G14: Casaca Ultimate | H14: 3 | I14: E000001 | J14: Oferta persuasiva | K14: 24/'02/2025 | L14: 0.50212963 | M14: Ver detalles
C15: C0000002 | D15: Steven | E15: Cadillo | F15: P0000002 | G15: Casaca Ligth | H15: 1 | I15: E000008 | J15: Producto alternativo | K15: 45680 | L15: 0.5437963 | M15: Ver detalles
C16: C0000003 | D16: Tino | E16: Reyna | F16: P0000003 | G16: Casaca Deluxe Verano | H16: 2 | I16: E000005 | J16: Producto alternativo | K16: ´10/01/2025 | L16: 0.58546296 | M16: Ver detalles
C17: ... | D17: ... | E17: ... | F17: .. | G17: ... | H17: ... | I17: ... | J17: ... | K17: ... | L17: ... | M17: ...
F20: 1 | G20: 2 | H20: 3 | I20: 4 | J20: 5
D25: DISEÑO LÓGICO
D27: tipo_producto | E27: char | F27: 6 | G27: PK | J27: clave primaria | K27: tipo_producto
D28: nombre_tipo_producto | E28: char | F28: 10 | G28: SK | J28: clave secundaria | K28: nombre_tipo_producto
D29: total_ventas | E29: int | F29: 3
D30: ventas | E30: ´1-99
E32: cod_cliente | F32: char | G32: 8 | H32: FK
E33: nombre | F33: char | G33: 20
E34: apellido | F34: char | G34: 20
E35: cod_producto | F35: char | G35: 8
E36: nombre_producto | F36: char | G36: 20
E37: cantidad | F37: int | G37: 3
E38: cod_estrategia | F38: char | G38: 8
E39: nombre_estrategia | F39: char | G39: 20
E40: fecha | F40: date | G40: 8
E41: hora | F41: date | G41: 8
B44: a. | C44: Nombre | D44: Tabla consulta Cierres de ventas - tipo Producto
C45: Organizacion | D45: Indexada
C46: Clave-Primaria | D46: tipo_producto
C47: Clave-Secundaria | D47: nombre_tipo_producto | K47: RL | L47: ER
H48: 10216 | K48: 0 | L48: 508
B49: b. | C49: Longitud-Registro | D49: (12196,2479) | J49: 512 | K49: 0 | L49: 1020
J50: 1024 | K50: 0 | L50: 10
B51: c. | C51: Espacio Libre | D51: (0,0) | J51: 1536 | K51: 0 | L51: 1532
J52: 2048 | K52: 1 | L52: 2044
B53: d. | C53: Longitud de BLOQUE (IC) | D53: 2560 | J53: 2560 | K53: 1 | L53: 74 | M53: se elige este
J54: 3072 | K54: 1 | L54: 1098
B55: e. | C55: Longitud de EXTENT (AC) | D55: 19*3*1 RLS | J55: 3584 | K55: 1 | L55: 1610
B57: f. | C57: Capacidad | D57: (N=1000000, AC= 19*3*2 RLS)
...
